<?xml version="1.0"?>
<sdf version='1.4'>
  <world name='default'>
    <scene>
      <ambient>0.5 0.5 0.5 1</ambient>
      <background>0.5 0.5 0.5 1</background>
      <shadows>0</shadows>
    </scene>
    <physics type='ode'>
      <gravity>0 0 -9.81</gravity>
      <ode>
        <solver>
          <type>quick</type>
          <iters>10</iters>
          <sor>1.3</sor>
        </solver>
        <constraints>
          <cfm>0</cfm>
          <erp>0.2</erp>
          <contact_max_correcting_vel>10</contact_max_correcting_vel>
          <contact_surface_layer>0.001</contact_surface_layer>
        </constraints>
      </ode>
      <max_step_size>0.001</max_step_size>
      <real_time_factor>1</real_time_factor>
      <real_time_update_rate>1000</real_time_update_rate>
    </physics>
    <light name='directional_light_1' type='directional'>
      <pose>0 20 20 0.1 0.1 0</pose>
      <diffuse>1 1 1 1</diffuse>
      <specular>1 1 1 1</specular>
      <attenuation>
        <range>300</range>
      </attenuation>
      <direction>0.1 0.1 -1</direction>
      <cast_shadows>0</cast_shadows>
    </light>
    <model name='tree1'>
      <static>1</static>
      <link name='tree1_link'>
        <pose>3 3 0.6 0 -0 0</pose>
        <collision name='tree1_collision'>
          <geometry>
            <mesh>
              <uri>file://OliveTree1.dae</uri>
              <scale>0.3 0.3 0.3</scale>
            </mesh>
          </geometry>
          <max_contacts>10</max_contacts>
          <surface>
            <bounce/>
            <friction>
              <ode/>
            </friction>
            <contact>
              <ode/>
            </contact>
          </surface>
        </collision>
        <visual name='tree1_visual'>
          <geometry>
            <mesh>
              <uri>file://OliveTree1.dae</uri>
              <scale>0.3 0.3 0.3</scale>
            </mesh>
          </geometry>
          <cast_shadows>0</cast_shadows>
        </visual>
        <velocity_decay>
          <linear>0</linear>
          <angular>0</angular>
        </velocity_decay>
        <self_collide>0</self_collide>
        <kinematic>0</kinematic>
        <gravity>1</gravity>
      </link>
    </model>
    <model name='tree2'>
      <static>1</static>
      <link name='tree2_link'>
        <pose>5 6 0.7 0 -0 0.3</pose>
        <collision name='tree2_collision'>
          <geometry>
            <mesh>
              <uri>file://OliveTree1.dae</uri>
              <scale>1 1 1</scale>
            </mesh>
          </geometry>
          <max_contacts>10</max_contacts>
          <surface>
            <bounce/>
            <friction>
              <ode/>
            </friction>
            <contact>
              <ode/>
            </contact>
          </surface>
        </collision>
        <visual name='tree2_visual'>
          <geometry>
            <mesh>
              <uri>file://OliveTree1.dae</uri>
              <scale>1 1 1</scale>
            </mesh>
          </geometry>
          <cast_shadows>0</cast_shadows>
        </visual>
        <velocity_decay>
          <linear>0</linear>
          <angular>0</angular>
        </velocity_decay>
        <self_collide>0</self_collide>
        <kinematic>0</kinematic>
        <gravity>1</gravity>
      </link>
    </model>
    <model name='tree3'>
      <static>1</static>
      <link name='tree3_link'>
        <pose>1 8 0.9 0 -0 0</pose>
        <collision name='tree3_collision'>
          <geometry>
            <mesh>
              <uri>file://OliveTree2.dae</uri>
              <scale>1 1 1</scale>
            </mesh>
          </geometry>
          <max_contacts>10</max_contacts>
          <surface>
            <bounce/>
            <friction>
              <ode/>
            </friction>
            <contact>
              <ode/>
            </contact>
          </surface>
        </collision>
        <visual name='tree3_visual'>
          <geometry>
            <mesh>
              <uri>file://OliveTree2.dae</uri>
              <scale>1 1 1</scale>
            </mesh>
          </geometry>
          <cast_shadows>0</cast_shadows>
        </visual>
        <velocity_decay>
          <linear>0</linear>
          <angular>0</angular>
        </velocity_decay>
        <self_collide>0</self_collide>
        <kinematic>0</kinematic>
        <gravity>1</gravity>
      </link>
    </model>
    <model name='tree4'>
      <static>1</static>
      <link name='tree4_link'>
        <pose>-5 4 0.8 0 -0 0.1</pose>
        <collision name='tree4_collision'>
          <geometry>
            <mesh>
              <uri>file://OliveTree1.dae</uri>
              <scale>1 1 1</scale>
            </mesh>
          </geometry>
          <max_contacts>10</max_contacts>
          <surface>
            <bounce/>
            <friction>
              <ode/>
            </friction>
            <contact>
              <ode/>
            </contact>
          </surface>
        </collision>
        <visual name='tree4_visual'>
          <geometry>
            <mesh>
              <uri>file://OliveTree1.dae</uri>
              <scale>1 1 1</scale>
            </mesh>
          </geometry>
          <cast_shadows>0</cast_shadows>
        </visual>
        <velocity_decay>
          <linear>0</linear>
          <angular>0</angular>
        </velocity_decay>
        <self_collide>0</self_collide>
        <kinematic>0</kinematic>
        <gravity>1</gravity>
      </link>
    </model>
    <model name='tree5'>
      <static>1</static>
      <link name='tree5_link'>
        <pose>-10 -3 1.1 0 -0 0.3</pose>
        <collision name='tree5_collision'>
          <geometry>
            <mesh>
              <uri>file://OliveTree1.dae</uri>
              <scale>1 1 1</scale>
            </mesh>
          </geometry>
          <max_contacts>10</max_contacts>
          <surface>
            <bounce/>
            <friction>
              <ode/>
            </friction>
            <contact>
              <ode/>
            </contact>
          </surface>
        </collision>
        <visual name='tree5_visual'>
          <geometry>
            <mesh>
              <uri>file://OliveTree1.dae</uri>
              <scale>1 1 1</scale>
            </mesh>
          </geometry>
          <cast_shadows>0</cast_shadows>
        </visual>
        <velocity_decay>
          <linear>0</linear>
          <angular>0</angular>
        </velocity_decay>
        <self_collide>0</self_collide>
        <kinematic>0</kinematic>
        <gravity>1</gravity>
      </link>
    </model>
    <model name='tree6'>
      <static>1</static>
      <link name='tree6_link'>
        <pose>-6 -7 1.02 0 -0 0.5</pose>
        <collision name='tree6_collision'>
          <geometry>
            <mesh>
              <uri>file://OliveTree1.dae</uri>
              <scale>1 1 1</scale>
            </mesh>
          </geometry>
          <max_contacts>10</max_contacts>
          <surface>
            <bounce/>
            <friction>
              <ode/>
            </friction>
            <contact>
              <ode/>
            </contact>
          </surface>
        </collision>
        <visual name='tree6_visual'>
          <geometry>
            <mesh>
              <uri>file://OliveTree1.dae</uri>
              <scale>1 1 1</scale>
            </mesh>
          </geometry>
          <cast_shadows>0</cast_shadows>
        </visual>
        <velocity_decay>
          <linear>0</linear>
          <angular>0</angular>
        </velocity_decay>
        <self_collide>0</self_collide>
        <kinematic>0</kinematic>
        <gravity>1</gravity>
      </link>
    </model>
    <model name='tree7'>
      <static>1</static>
      <link name='tree7_link'>
        <pose>-1 -6 0.8 0 -0 0.2</pose>
        <collision name='tree7_collision'>
          <geometry>
            <mesh>
              <uri>file://OliveTree2.dae</uri>
              <scale>1 1 1</scale>
            </mesh>
          </geometry>
          <max_contacts>10</max_contacts>
          <surface>
            <bounce/>
            <friction>
              <ode/>
            </friction>
            <contact>
              <ode/>
            </contact>
          </surface>
        </collision>
        <visual name='tree7_visual'>
          <geometry>
            <mesh>
              <uri>file://OliveTree2.dae</uri>
              <scale>1 1 1</scale>
            </mesh>
          </geometry>
          <cast_shadows>0</cast_shadows>
        </visual>
        <velocity_decay>
          <linear>0</linear>
          <angular>0</angular>
        </velocity_decay>
        <self_collide>0</self_collide>
        <kinematic>0</kinematic>
        <gravity>1</gravity>
      </link>
    </model>
    <model name='tree8'>
      <static>1</static>
      <link name='tree8_link'>
        <pose>9 -4 0.5 0 -0 0.5</pose>
        <collision name='tree8_collision'>
          <geometry>
            <mesh>
              <uri>file://OliveTree1.dae</uri>
              <scale>1 1 1</scale>
            </mesh>
          </geometry>
          <max_contacts>10</max_contacts>
          <surface>
            <bounce/>
            <friction>
              <ode/>
            </friction>
            <contact>
              <ode/>
            </contact>
          </surface>
        </collision>
        <visual name='tree8_visual'>
          <geometry>
            <mesh>
              <uri>file://OliveTree1.dae</uri>
              <scale>1 1 1</scale>
            </mesh>
          </geometry>
          <cast_shadows>0</cast_shadows>
        </visual>
        <velocity_decay>
          <linear>0</linear>
          <angular>0</angular>
        </velocity_decay>
        <self_collide>0</self_collide>
        <kinematic>0</kinematic>
        <gravity>1</gravity>
      </link>
    </model>
    <model name='tree9'>
      <static>1</static>
      <link name='tree9_link'>
        <pose>6 -10 0.8 0 -0 0.5</pose>
        <collision name='tree9_collision'>
          <geometry>
            <mesh>
              <uri>file://OliveTree1.dae</uri>
              <scale>1 1 1</scale>
            </mesh>
          </geometry>
          <max_contacts>10</max_contacts>
          <surface>
            <bounce/>
            <friction>
              <ode/>
            </friction>
            <contact>
              <ode/>
            </contact>
          </surface>
        </collision>
        <visual name='tree9_visual'>
          <geometry>
            <mesh>
              <uri>file://OliveTree1.dae</uri>
              <scale>1 1 1</scale>
            </mesh>
          </geometry>
          <cast_shadows>0</cast_shadows>
        </visual>
        <velocity_decay>
          <linear>0</linear>
          <angular>0</angular>
        </velocity_decay>
        <self_collide>0</self_collide>
        <kinematic>0</kinematic>
        <gravity>1</gravity>
      </link>
    </model>
    <spherical_coordinates>
      <surface_model>EARTH_WGS84</surface_model>
      <latitude_deg>0</latitude_deg>
      <longitude_deg>0</longitude_deg>
      <elevation>0</elevation>
      <heading_deg>0</heading_deg>
    </spherical_coordinates>
    <model name='jackal'>
      <link name='base_link'>
        <pose>0 0 0 0 -0 0</pose>
        <inertial>
          <pose>0.0187401 0.00187506 0.0835986 0 -0 0</pose>
          <mass>17.624</mass>
          <inertia>
            <ixx>0.389656</ixx>
            <ixy>-0.000577266</ixy>
            <ixz>-0.0132299</ixz>
            <iyy>0.480339</iyy>
            <iyz>-0.000351484</iyz>
            <izz>0.462498</izz>
          </inertia>
        </inertial>
        <collision name='base_link_collision_chassis_link'>
          <pose>0 0 0.092 0 -0 0</pose>
          <geometry>
            <box>
              <size>0.42 0.31 0.184</size>
            </box>
          </geometry>
          <surface>
            <contact>
              <ode/>
            </contact>
            <friction>
              <ode/>
            </friction>
            <bounce/>
          </surface>
          <surface>
            <contact>
              <ode/>
            </contact>
            <friction>
              <ode/>
            </friction>
          </surface>
          <max_contacts>10</max_contacts>
        </collision>
        <collision name='base_link_collision_front_laser'>
          <pose>0.12 0 0.283 0 -0 0</pose>
          <geometry>
            <box>
              <size>0.105 0.1 0.1</size>
            </box>
          </geometry>
          <surface>
            <contact>
              <ode/>
            </contact>
            <friction>
              <ode/>
            </friction>
            <bounce/>
          </surface>
          <surface>
            <contact>
              <ode/>
            </contact>
            <friction>
              <ode/>
            </friction>
          </surface>
          <max_contacts>10</max_contacts>
        </collision>
        <visual name='base_link_visual_chassis_link'>
          <pose>0 0 -0.0655 1.5708 -5.55112e-17 1.5708</pose>
          <geometry>
            <mesh>
              <scale>1 1 1</scale>
              <uri>/opt/ros/indigo/share/jackal_description/meshes/jackal-base.stl</uri>
            </mesh>
          </geometry>
          <material>
            <script>
              <name>Gazebo/DarkGrey</name>
              <uri>__default__</uri>
            </script>
          </material>
        </visual>
        <visual name='base_link_visual_fenders_link'>
          <pose>0 0 -0.0655 1.5708 -5.55112e-17 1.5708</pose>
          <geometry>
            <mesh>
              <scale>1 1 1</scale>
              <uri>/opt/ros/indigo/share/jackal_description/meshes/jackal-fenders.stl</uri>
            </mesh>
          </geometry>
          <material>
            <script>
              <name>Gazebo/Yellow</name>
              <uri>__default__</uri>
            </script>
          </material>
        </visual>
        <visual name='base_link_visual_front_laser'>
          <pose>0.12 0 0.333 0 -0 0</pose>
          <geometry>
            <mesh>
              <scale>1 1 1</scale>
              <uri>/opt/ros/indigo/share/lms1xx/meshes/sick-lms1xx.dae</uri>
            </mesh>
          </geometry>
        </visual>
        <visual name='base_link_visual_front_laser_mount'>
          <pose>0.12 0 0.184 0 -0 0</pose>
          <geometry>
            <mesh>
              <scale>1 1 1</scale>
              <uri>/opt/ros/indigo/share/jackal_description/meshes/sick-lms1xx-bracket.stl</uri>
            </mesh>
          </geometry>
          <material>
            <script>
              <name>Gazebo/DarkGrey</name>
              <uri>__default__</uri>
            </script>
          </material>
        </visual>
        <visual name='base_link_visual_navsat_link'>
          <pose>-0.18 0.126 0.1895 0 -0 0</pose>
          <geometry>
            <cylinder>
              <length>0.016</length>
              <radius>0.026</radius>
            </cylinder>
          </geometry>
          <material>
            <script>
              <name>Gazebo/DarkGrey</name>
              <uri>__default__</uri>
            </script>
          </material>
        </visual>
        <velocity_decay>
          <linear>0</linear>
          <angular>0</angular>
        </velocity_decay>
        <velocity_decay>
          <linear>0</linear>
          <angular>0</angular>
        </velocity_decay>
        <velocity_decay>
          <linear>0</linear>
          <angular>0</angular>
        </velocity_decay>
        <velocity_decay>
          <linear>0</linear>
          <angular>0</angular>
        </velocity_decay>
        <velocity_decay>
          <linear>0</linear>
          <angular>0</angular>
        </velocity_decay>
        <velocity_decay>
          <linear>0</linear>
          <angular>0</angular>
        </velocity_decay>
        <sensor name='front_laser' type='ray'>
          <visualize>0</visualize>
          <update_rate>50</update_rate>
          <ray>
            <scan>
              <horizontal>
                <samples>720</samples>
                <resolution>1</resolution>
                <min_angle>-2.35619</min_angle>
                <max_angle>2.35619</max_angle>
              </horizontal>
            </scan>
            <range>
              <min>0.1</min>
              <max>30</max>
              <resolution>0.01</resolution>
            </range>
            <noise>
              <type>gaussian</type>
              <mean>0</mean>
              <stddev>0.001</stddev>
            </noise>
          </ray>
          <plugin name='gazebo_ros_laser' filename='libgazebo_ros_laser.so'>
            <topicName>front/scan</topicName>
            <frameName>front_laser</frameName>
            <robotNamespace>/</robotNamespace>
          </plugin>
          <pose>0.12 0 0.333 0 -0 0</pose>
        </sensor>
        <gravity>1</gravity>
        <velocity_decay>
          <linear>0</linear>
          <angular>0</angular>
        </velocity_decay>
        <self_collide>0</self_collide>
        <kinematic>0</kinematic>
      </link>
      <link name='front_left_wheel_link'>
        <pose>0.131 0.187795 0.0345 0 -0 0</pose>
        <inertial>
          <pose>0 0 0 0 -0 0</pose>
          <mass>0.477</mass>
          <inertia>
            <ixx>0.0013</ixx>
            <ixy>0</ixy>
            <ixz>0</ixz>
            <iyy>0.0024</iyy>
            <iyz>0</iyz>
            <izz>0.0013</izz>
          </inertia>
        </inertial>
        <collision name='front_left_wheel_link_collision'>
          <pose>0 0 0 1.5708 -0 0</pose>
          <geometry>
            <cylinder>
              <length>0.04</length>
              <radius>0.098</radius>
            </cylinder>
          </geometry>
          <surface>
            <contact>
              <ode/>
            </contact>
            <friction>
              <ode/>
            </friction>
            <bounce/>
          </surface>
          <max_contacts>10</max_contacts>
        </collision>
        <visual name='front_left_wheel_link_visual'>
          <pose>0 0 0 1.5708 -0 0</pose>
          <geometry>
            <mesh>
              <scale>1 1 1</scale>
              <uri>/opt/ros/indigo/share/jackal_description/meshes/jackal-wheel.stl</uri>
            </mesh>
          </geometry>
          <material>
            <script>
              <name>Gazebo/DarkGrey</name>
              <uri>__default__</uri>
            </script>
          </material>
        </visual>
        <gravity>1</gravity>
        <velocity_decay>
          <linear>0</linear>
          <angular>0</angular>
        </velocity_decay>
        <self_collide>0</self_collide>
        <kinematic>0</kinematic>
      </link>
      <joint name='front_left_wheel' type='revolute'>
        <child>front_left_wheel_link</child>
        <parent>base_link</parent>
        <axis>
          <xyz>0 1 0</xyz>
          <limit>
            <lower>-1e+16</lower>
            <upper>1e+16</upper>
          </limit>
          <dynamics/>
        </axis>
      </joint>
      <link name='front_right_wheel_link'>
        <pose>0.131 -0.187795 0.0345 0 -0 0</pose>
        <inertial>
          <pose>0 0 0 0 -0 0</pose>
          <mass>0.477</mass>
          <inertia>
            <ixx>0.0013</ixx>
            <ixy>0</ixy>
            <ixz>0</ixz>
            <iyy>0.0024</iyy>
            <iyz>0</iyz>
            <izz>0.0013</izz>
          </inertia>
        </inertial>
        <collision name='front_right_wheel_link_collision'>
          <pose>0 0 0 1.5708 -0 0</pose>
          <geometry>
            <cylinder>
              <length>0.04</length>
              <radius>0.098</radius>
            </cylinder>
          </geometry>
          <surface>
            <contact>
              <ode/>
            </contact>
            <friction>
              <ode/>
            </friction>
            <bounce/>
          </surface>
          <max_contacts>10</max_contacts>
        </collision>
        <visual name='front_right_wheel_link_visual'>
          <pose>0 0 0 1.5708 -0 0</pose>
          <geometry>
            <mesh>
              <scale>1 1 1</scale>
              <uri>/opt/ros/indigo/share/jackal_description/meshes/jackal-wheel.stl</uri>
            </mesh>
          </geometry>
          <material>
            <script>
              <name>Gazebo/DarkGrey</name>
              <uri>__default__</uri>
            </script>
          </material>
        </visual>
        <gravity>1</gravity>
        <velocity_decay>
          <linear>0</linear>
          <angular>0</angular>
        </velocity_decay>
        <self_collide>0</self_collide>
        <kinematic>0</kinematic>
      </link>
      <joint name='front_right_wheel' type='revolute'>
        <child>front_right_wheel_link</child>
        <parent>base_link</parent>
        <axis>
          <xyz>0 1 0</xyz>
          <limit>
            <lower>-1e+16</lower>
            <upper>1e+16</upper>
          </limit>
          <dynamics/>
        </axis>
      </joint>
      <link name='rear_left_wheel_link'>
        <pose>-0.131 0.187795 0.0345 0 -0 0</pose>
        <inertial>
          <pose>0 0 0 0 -0 0</pose>
          <mass>0.477</mass>
          <inertia>
            <ixx>0.0013</ixx>
            <ixy>0</ixy>
            <ixz>0</ixz>
            <iyy>0.0024</iyy>
            <iyz>0</iyz>
            <izz>0.0013</izz>
          </inertia>
        </inertial>
        <collision name='rear_left_wheel_link_collision'>
          <pose>0 0 0 1.5708 -0 0</pose>
          <geometry>
            <cylinder>
              <length>0.04</length>
              <radius>0.098</radius>
            </cylinder>
          </geometry>
          <surface>
            <contact>
              <ode/>
            </contact>
            <friction>
              <ode/>
            </friction>
            <bounce/>
          </surface>
          <max_contacts>10</max_contacts>
        </collision>
        <visual name='rear_left_wheel_link_visual'>
          <pose>0 0 0 1.5708 -0 0</pose>
          <geometry>
            <mesh>
              <scale>1 1 1</scale>
              <uri>/opt/ros/indigo/share/jackal_description/meshes/jackal-wheel.stl</uri>
            </mesh>
          </geometry>
          <material>
            <script>
              <name>Gazebo/DarkGrey</name>
              <uri>__default__</uri>
            </script>
          </material>
        </visual>
        <gravity>1</gravity>
        <velocity_decay>
          <linear>0</linear>
          <angular>0</angular>
        </velocity_decay>
        <self_collide>0</self_collide>
        <kinematic>0</kinematic>
      </link>
      <joint name='rear_left_wheel' type='revolute'>
        <child>rear_left_wheel_link</child>
        <parent>base_link</parent>
        <axis>
          <xyz>0 1 0</xyz>
          <limit>
            <lower>-1e+16</lower>
            <upper>1e+16</upper>
          </limit>
          <dynamics/>
        </axis>
      </joint>
      <link name='rear_right_wheel_link'>
        <pose>-0.131 -0.187795 0.0345 0 -0 0</pose>
        <inertial>
          <pose>0 0 0 0 -0 0</pose>
          <mass>0.477</mass>
          <inertia>
            <ixx>0.0013</ixx>
            <ixy>0</ixy>
            <ixz>0</ixz>
            <iyy>0.0024</iyy>
            <iyz>0</iyz>
            <izz>0.0013</izz>
          </inertia>
        </inertial>
        <collision name='rear_right_wheel_link_collision'>
          <pose>0 0 0 1.5708 -0 0</pose>
          <geometry>
            <cylinder>
              <length>0.04</length>
              <radius>0.098</radius>
            </cylinder>
          </geometry>
          <surface>
            <contact>
              <ode/>
            </contact>
            <friction>
              <ode/>
            </friction>
            <bounce/>
          </surface>
          <max_contacts>10</max_contacts>
        </collision>
        <visual name='rear_right_wheel_link_visual'>
          <pose>0 0 0 1.5708 -0 0</pose>
          <geometry>
            <mesh>
              <scale>1 1 1</scale>
              <uri>/opt/ros/indigo/share/jackal_description/meshes/jackal-wheel.stl</uri>
            </mesh>
          </geometry>
          <material>
            <script>
              <name>Gazebo/DarkGrey</name>
              <uri>__default__</uri>
            </script>
          </material>
        </visual>
        <gravity>1</gravity>
        <velocity_decay>
          <linear>0</linear>
          <angular>0</angular>
        </velocity_decay>
        <self_collide>0</self_collide>
        <kinematic>0</kinematic>
      </link>
      <joint name='rear_right_wheel' type='revolute'>
        <child>rear_right_wheel_link</child>
        <parent>base_link</parent>
        <axis>
          <xyz>0 1 0</xyz>
          <limit>
            <lower>-1e+16</lower>
            <upper>1e+16</upper>
          </limit>
          <dynamics/>
        </axis>
      </joint>
      <plugin name='gazebo_ros_control' filename='libgazebo_ros_control.so'>
        <robotNamespace>/</robotNamespace>
      </plugin>
      <plugin name='imu_controller' filename='libhector_gazebo_ros_imu.so'>
        <robotNamespace>/</robotNamespace>
        <updateRate>50.0</updateRate>
        <topicName>imu/data</topicName>
        <accelDrift>0.005 0.005 0.005</accelDrift>
        <accelGaussianNoise>0.005 0.005 0.005</accelGaussianNoise>
        <rateDrift>0.005 0.005 0.005</rateDrift>
        <rateGaussianNoise>0.005 0.005 0.005</rateGaussianNoise>
        <headingDrift>0.005</headingDrift>
        <headingGaussianNoise>0.005</headingGaussianNoise>
        <bodyName>base_link</bodyName>
        <xyzOffset>0 0 0</xyzOffset>
        <rpyOffset>0 -0 0</rpyOffset>
      </plugin>
      <static>0</static>
      <plugin name='gps_controller' filename='libhector_gazebo_ros_gps.so'>
        <updateRate>40</updateRate>
        <robotNamespace>/</robotNamespace>
        <frameId>base_link</frameId>
        <topicName>/navsat/fix</topicName>
        <velocityTopicName>/navsat/vel</velocityTopicName>
        <referenceLatitude>49.9</referenceLatitude>
        <referenceLongitude>8.9</referenceLongitude>
        <referenceHeading>0</referenceHeading>
        <referenceAltitude>0</referenceAltitude>
        <drift>0.0001 0.0001 0.0001</drift>
        <bodyName>base_link</bodyName>
        <xyzOffset>0.18 -0.126 -0.1815</xyzOffset>
        <rpyOffset>0 -0 0</rpyOffset>
      </plugin>
      <pose>0 0 1 0 -0 0</pose>
    </model>
    <model name='asphalt_plane'>
      <static>1</static>
      <link name='link'>
        <collision name='collision'>
          <geometry>
            <box>
              <size>20 20 0.1</size>
            </box>
          </geometry>
          <max_contacts>10</max_contacts>
          <surface>
            <bounce/>
            <friction>
              <ode/>
            </friction>
            <contact>
              <ode/>
            </contact>
          </surface>
        </collision>
        <visual name='visual'>
          <cast_shadows>0</cast_shadows>
          <geometry>
            <box>
              <size>20 20 0.1</size>
            </box>
          </geometry>
          <material>
            <script>
              <uri>model://asphalt_plane/materials/scripts</uri>
              <uri>model://asphalt_plane/materials/textures</uri>
              <name>vrc/asphalt</name>
            </script>
          </material>
        </visual>
        <velocity_decay>
          <linear>0</linear>
          <angular>0</angular>
        </velocity_decay>
        <self_collide>0</self_collide>
        <kinematic>0</kinematic>
        <gravity>1</gravity>
      </link>
      <pose>-32 5 0 0 -0 0</pose>
    </model>
    <state world_name='default'>
      <sim_time>109 7000000</sim_time>
      <real_time>110 70740445</real_time>
      <wall_time>1469381325 183257453</wall_time>
      <model name='asphalt_plane'>
        <pose>0.067204 -0.024812 0 0 -0 0</pose>
        <link name='link'>
          <pose>0.067204 -0.024812 0 0 -0 0</pose>
          <velocity>0 0 0 0 -0 0</velocity>
          <acceleration>0 0 0 0 -0 0</acceleration>
          <wrench>0 0 0 0 -0 0</wrench>
        </link>
      </model>
      <model name='jackal'>
        <pose>0.789472 0.012559 -40611.2 -0.209481 -0.130462 0.006823</pose>
        <link name='base_link'>
          <pose>0.789472 0.012559 -40611.2 -0.209481 -0.130462 0.006823</pose>
          <velocity>0.007443 -0.000158 -892.637 -0.002419 -0.002227 -0.000434</velocity>
          <acceleration>0 0 -9.81 0 -0 0</acceleration>
          <wrench>0 0 -172.891 0 -0 0</wrench>
        </link>
        <link name='front_left_wheel_link'>
          <pose>0.918744 0.20431 -40611.2 -0.22718 0.414192 -0.113595</pose>
          <velocity>0.0075 -0.000185 -892.637 -0.002419 -0.002227 -0.000434</velocity>
          <acceleration>0 -0 -9.81 0 -0 0</acceleration>
          <wrench>0 -0 -4.67937 0 -0 0</wrench>
        </link>
        <link name='front_right_wheel_link'>
          <pose>0.91109 -0.16313 -40611.1 -0.232435 0.462131 -0.125978</pose>
          <velocity>0.007168 6e-06 -892.637 -0.002419 -0.002227 -0.000434</velocity>
          <acceleration>-2e-06 2e-06 -9.81 0 -0 0</acceleration>
          <wrench>-1e-06 1e-06 -4.67937 0 -0 0</wrench>
        </link>
        <link name='rear_left_wheel_link'>
          <pose>0.658977 0.202537 -40611.2 -0.209115 0.116567 -0.045504</pose>
          <velocity>0.007575 -0.000155 -892.638 -0.002419 -0.002227 -0.000434</velocity>
          <acceleration>2e-06 -2e-06 -9.81 0 -0 0</acceleration>
          <wrench>1e-06 -1e-06 -4.67937 0 -0 0</wrench>
        </link>
        <link name='rear_right_wheel_link'>
          <pose>0.651323 -0.164903 -40611.1 -0.213058 0.2236 -0.068762</pose>
          <velocity>0.007243 3.6e-05 -892.637 -0.002419 -0.002227 -0.000434</velocity>
          <acceleration>-0 0 -9.81 0 -0 0</acceleration>
          <wrench>-0 0 -4.67937 0 -0 0</wrench>
        </link>
      </model>
      <model name='tree1'>
        <pose>0 0 0 0 -0 0</pose>
        <link name='tree1_link'>
          <pose>3 3 0.6 0 -0 0</pose>
          <velocity>0 0 0 0 -0 0</velocity>
          <acceleration>0 0 0 0 -0 0</acceleration>
          <wrench>0 0 0 0 -0 0</wrench>
        </link>
      </model>
      <model name='tree2'>
        <pose>-0 -0 0 0 -0 0</pose>
        <link name='tree2_link'>
          <pose>5 6 0.7 0 -0 0.3</pose>
          <velocity>0 0 0 0 -0 0</velocity>
          <acceleration>0 0 0 0 -0 0</acceleration>
          <wrench>0 0 0 0 -0 0</wrench>
        </link>
      </model>
      <model name='tree3'>
        <pose>0 0 0 0 -0 0</pose>
        <link name='tree3_link'>
          <pose>1 8 0.9 0 -0 0</pose>
          <velocity>0 0 0 0 -0 0</velocity>
          <acceleration>0 0 0 0 -0 0</acceleration>
          <wrench>0 0 0 0 -0 0</wrench>
        </link>
      </model>
      <model name='tree4'>
        <pose>0 -0 0 0 -0 0</pose>
        <link name='tree4_link'>
          <pose>-5 4 0.8 0 -0 0.1</pose>
          <velocity>0 0 0 0 -0 0</velocity>
          <acceleration>0 0 0 0 -0 0</acceleration>
          <wrench>0 0 0 0 -0 0</wrench>
        </link>
      </model>
      <model name='tree5'>
        <pose>0 0 0 0 -0 0</pose>
        <link name='tree5_link'>
          <pose>-10 -3 1.1 0 -0 0.3</pose>
          <velocity>0 0 0 0 -0 0</velocity>
          <acceleration>0 0 0 0 -0 0</acceleration>
          <wrench>0 0 0 0 -0 0</wrench>
        </link>
      </model>
      <model name='tree6'>
        <pose>-0 -0 0 0 -0 0</pose>
        <link name='tree6_link'>
          <pose>-6 -7 1.02 0 -0 0.5</pose>
          <velocity>0 0 0 0 -0 0</velocity>
          <acceleration>0 0 0 0 -0 0</acceleration>
          <wrench>0 0 0 0 -0 0</wrench>
        </link>
      </model>
      <model name='tree7'>
        <pose>0 0 0 0 -0 0</pose>
        <link name='tree7_link'>
          <pose>-1 -6 0.8 0 -0 0.2</pose>
          <velocity>0 0 0 0 -0 0</velocity>
          <acceleration>0 0 0 0 -0 0</acceleration>
          <wrench>0 0 0 0 -0 0</wrench>
        </link>
      </model>
      <model name='tree8'>
        <pose>0 -0 0 0 -0 0</pose>
        <link name='tree8_link'>
          <pose>9 -4 0.5 0 -0 0.5</pose>
          <velocity>0 0 0 0 -0 0</velocity>
          <acceleration>0 0 0 0 -0 0</acceleration>
          <wrench>0 0 0 0 -0 0</wrench>
        </link>
      </model>
      <model name='tree9'>
        <pose>0 -0 0 0 -0 0</pose>
        <link name='tree9_link'>
          <pose>6 -10 0.8 0 -0 0.5</pose>
          <velocity>0 0 0 0 -0 0</velocity>
          <acceleration>0 0 0 0 -0 0</acceleration>
          <wrench>0 0 0 0 -0 0</wrench>
        </link>
      </model>
    </state>
    <gui fullscreen='0'>
      <camera name='user_camera'>
        <pose>26.6203 -3.87551 17.437 -1.61766e-17 0.539643 2.84419</pose>
        <view_controller>orbit</view_controller>
      </camera>
    </gui>
  </world>
</sdf>
